Interpreted as UCCM data and failed:
Handling post request
b'imei=300234068129370&device_type=ROCKBLOCK&serial=16967&momsn=757&transmit_time=22-03-13%2018%3A49%3A21&iridium_latitude=49.2602&iridium_longitude=-123.2174&iridium_cep=2.0&iridium_session_status=0&data=08011abb010a0a080c1006182022024f4e120a08041005180422024f4e1a0a08041005180422024f4e220a08041005180422024f4e2a0a08041005180422024f4e320a08041005182822024f4e3a0a08041005182822024f4e420a08041005182822024f4e52005a00620a08041005180222024f4e6a0a08041005180222024f4e720a08041005180222024f4e7a0a08041005180222024f4e82010a08041005180222024f4e8a010a08041005180222024f4e92010a08041005180222024f4e'
08011abb010a0a080c1006182022024f4e120a08041005180422024f4e1a0a08041005180422024f4e220a08041005180422024f4e2a0a08041005180422024f4e320a08041005182822024f4e3a0a08041005182822024f4e420a08041005182822024f4e52005a00620a08041005180222024f4e6a0a08041005180222024f4e720a08041005180222024f4e7a0a08041005180222024f4e82010a08041005180222024f4e8a010a08041005180222024f4e92010a08041005180222024f4e
Receiving UCCM Data
----------------------------------------
Exception happened during processing of request from ('212.71.235.32', 55802)
Traceback (most recent call last):
  File "/usr/lib/python3.6/socketserver.py", line 320, in _handle_request_noblock
    self.process_request(request, client_address)
  File "/usr/lib/python3.6/socketserver.py", line 351, in process_request
    self.finish_request(request, client_address)
  File "/usr/lib/python3.6/socketserver.py", line 364, in finish_request
    self.RequestHandlerClass(request, client_address, self)
  File "land_satellite_listener.py", line 34, in __init__
    super().__init__(*args, **kwargs)
  File "/usr/lib/python3.6/socketserver.py", line 724, in __init__
    self.handle()
  File "/usr/lib/python3.6/http/server.py", line 418, in handle
    self.handle_one_request()
  File "/usr/lib/python3.6/http/server.py", line 406, in handle_one_request
    method()
  File "land_satellite_listener.py", line 65, in do_POST
    values = helper.uccms_to_root(sat.uccms)
  File "/root/network-table/projects/land_satellite_listener/nt_connection/Help.py", line 229, in uccms_to_root
    val = self.create_int_val(uccms.gps_0.current)
AttributeError: gps_0
----------------------------------------

Failing because uccms does not have gps_0. This is from running the pre-existing stress client on the BBB.
